<robot name="iCubHeidelberg01_SIM_MODEL">
  <link name="root_link">
    <inertial>
      <origin xyz="0.0251137 0.000104218 -0.0437451" rpy="1.57079632679 0 -1.57079632679"/>
      <mass value="5.1504"/>
      <inertia ixx="0.0140911" ixy="6.63933e-05" ixz="-8.71849e-05" iyy="0.0205529" iyz="-0.00172034" izz="0.0252712"/>
    </inertial>
  </link>
  <link name="r_hip_1">
    <inertial>
      <origin xyz="-0.0529681 -4e-05 -0.0005388" rpy="0 0 0"/>
      <mass value="0.9279"/>
      <inertia ixx="0.000403391" ixy="-1.44877e-06" ixz="2.87683e-06" iyy="0.000572457" iyz="-1.70772e-07" izz="0.00057759"/>
    </inertial>
  </link>
  <joint name="r_hip_pitch" type="revolute">
    <origin xyz="0.0064515 0.0111 -0.119913" rpy="1.57079632679 0 -1.57079632679"/>
    <axis xyz="-1.0 0.0 0.0"/>
    <parent link="root_link"/>
    <child link="r_hip_1"/>
    <limit effort="50000" lower="-0.523598775598" upper="1.4835298642" velocity="50000"/>
    <dynamics damping="0.223"/>
  </joint>
  <link name="r_hip_2">
    <inertial>
      <origin xyz="3.49999999999e-06 -0.044278 0.0249831" rpy="0 0 0"/>
      <mass value="0.4184"/>
      <inertia ixx="0.000487899" ixy="-2.35279e-07" ixz="1.93211e-07" iyy="0.000286147" iyz="1.23695e-05" izz="0.000315134"/>
    </inertial>
  </link>
  <joint name="r_hip_roll" type="revolute">
    <origin xyz="-0.059 0 -0.0263622" rpy="0 0 0"/>
    <axis xyz="0.0 0.0 -1.0"/>
    <parent link="r_hip_1"/>
    <child link="r_hip_2"/>
    <limit effort="50000" lower="0.0" upper="1.57079632679" velocity="50000"/>
    <dynamics damping="0.223"/>
  </joint>
  <link name="r_hip_3">
    <inertial>
      <origin xyz="-0.000123 -0.0002823 0.008718" rpy="-1.57079632679 0 -1.57079632679"/>
      <mass value="0.1262"/>
      <inertia ixx="3.34665e-05" ixy="7.47286e-08" ixz="-4.04554e-08" iyy="5.70757e-05" iyz="-8.80407e-08" izz="3.33523e-05"/>
    </inertial>
  </link>
  <joint name="r_leg_ft_sensor" type="fixed">
    <origin xyz="0 -0.0743 0.0255047" rpy="1.57079632679 -1.57079632679 0"/>
    <parent link="r_hip_2"/>
    <child link="r_hip_3"/>
    <dynamics damping="0.1"/>
  </joint>
  <link name="r_upper_leg">
    <inertial>
      <origin xyz="-5.89e-05 -0.079146 0.0033012" rpy="0 0 0"/>
      <mass value="2.2544"/>
      <inertia ixx="0.00794621" ixy="0.000169783" ixz="9.58795e-06" iyy="0.00179234" iyz="-0.000163445" izz="0.00796958"/>
    </inertial>
  </link>
  <joint name="r_hip_yaw" type="revolute">
    <origin xyz="0 0 0.018" rpy="-1.57079632679 0 -1.57079632679"/>
    <axis xyz="0.0 -1.0 0.0"/>
    <parent link="r_hip_3"/>
    <child link="r_upper_leg"/>
    <limit effort="50000" lower="-1.2217304764" upper="1.2217304764" velocity="50000"/>
    <dynamics damping="0.223"/>
  </joint>
  <link name="r_upper_leg_acc_mtb_11B4"/>
  <joint name="r_upper_leg_acc_mtb_11B4_fixed_joint" type="fixed">
    <origin xyz="0.0414996 -0.011459 0.03416985" rpy="-1.18682376736 0.000365167547861 -1.57082213412"/>
    <parent link="r_upper_leg"/>
    <child link="r_upper_leg_acc_mtb_11B4"/>
    <dynamics damping="0.1"/>
  </joint>
  <link name="r_upper_leg_acc_mtb_11B7"/>
  <joint name="r_upper_leg_acc_mtb_11B7_fixed_joint" type="fixed">
    <origin xyz="0.0162386 -0.026366 -0.0437518" rpy="3.14159260377 0.000429089990404 -1.57091243007"/>
    <parent link="r_upper_leg"/>
    <child link="r_upper_leg_acc_mtb_11B7"/>
    <dynamics damping="0.1"/>
  </joint>
  <link name="r_upper_leg_acc_mtb_11B6"/>
  <joint name="r_upper_leg_acc_mtb_11B6_fixed_joint" type="fixed">
    <origin xyz="-0.0157594 -0.026365 -0.0437518" rpy="3.14159265359 0.000429089993416 -1.57079632679"/>
    <parent link="r_upper_leg"/>
    <child link="r_upper_leg_acc_mtb_11B6"/>
    <dynamics damping="0.1"/>
  </joint>
  <link name="r_upper_leg_acc_mtb_11B1"/>
  <joint name="r_upper_leg_acc_mtb_11B1_fixed_joint" type="fixed">
    <origin xyz="-0.031565 0.042526 0.04206438" rpy="0.837758053214 0.000342816436844 -1.57071863125"/>
    <parent link="r_upper_leg"/>
    <child link="r_upper_leg_acc_mtb_11B1"/>
    <dynamics damping="0.1"/>
  </joint>
  <link name="r_upper_leg_acc_mtb_11B2"/>
  <joint name="r_upper_leg_acc_mtb_11B2_fixed_joint" type="fixed">
    <origin xyz="-0.0083839 0.032642 0.05341396" rpy="0.26179934248 0.000399026344981 -1.5706841771"/>
    <parent link="r_upper_leg"/>
    <child link="r_upper_leg_acc_mtb_11B2"/>
    <dynamics damping="0.1"/>
  </joint>
  <link name="r_upper_leg_acc_mtb_11B3"/>
  <joint name="r_upper_leg_acc_mtb_11B3_fixed_joint" type="fixed">
    <origin xyz="-0.0150686 -0.002429 0.0538284" rpy="0 0.000429089990404 -1.57068022352"/>
    <parent link="r_upper_leg"/>
    <child link="r_upper_leg_acc_mtb_11B3"/>
    <dynamics damping="0.1"/>
  </joint>
  <link name="r_upper_leg_acc_mtb_11B5"/>
  <joint name="r_upper_leg_acc_mtb_11B5_fixed_joint" type="fixed">
    <origin xyz="0.0144314 -0.002429 0.0538284" rpy="0 0.000429089990404 -1.57068022352"/>
    <parent link="r_upper_leg"/>
    <child link="r_upper_leg_acc_mtb_11B5"/>
    <dynamics damping="0.1"/>
  </joint>
  <link name="r_lower_leg">
    <inertial>
      <origin xyz="0.0117639 -0.083358 0.0024521" rpy="0 0 0"/>
      <mass value="1.7086"/>
      <inertia ixx="0.00565145" ixy="0.000651976" ixz="1.347e-05" iyy="0.00170964" iyz="-0.000147573" izz="0.00615412"/>
    </inertial>
  </link>
  <joint name="r_knee" type="revolute">
    <origin xyz="-0.017957 -0.145625 0" rpy="0 0 0"/>
    <axis xyz="-1.0 0.0 0.0"/>
    <parent link="r_upper_leg"/>
    <child link="r_lower_leg"/>
    <limit effort="50000" lower="-1.74532925199" upper="0.0" velocity="50000"/>
    <dynamics damping="0.223"/>
  </joint>
  <link name="r_lower_leg_acc_mtb_11B9"/>
  <joint name="r_lower_leg_acc_mtb_11B9_fixed_joint" type="fixed">
    <origin xyz="0.0279561 -0.010933 0.0544518" rpy="-0.349065638037 3.9709492862e-05 -1.57068722577"/>
    <parent link="r_lower_leg"/>
    <child link="r_lower_leg_acc_mtb_11B9"/>
    <dynamics damping="0.1"/>
  </joint>
  <link name="r_lower_leg_acc_mtb_11B8"/>
  <joint name="r_lower_leg_acc_mtb_11B8_fixed_joint" type="fixed">
    <origin xyz="-0.0030252 -0.010933 0.05313395" rpy="0.244346164411 -2.808784262e-05 -1.57068367232"/>
    <parent link="r_lower_leg"/>
    <child link="r_lower_leg_acc_mtb_11B8"/>
    <dynamics damping="0.1"/>
  </joint>
  <link name="r_lower_leg_acc_mtb_11B10"/>
  <joint name="r_lower_leg_acc_mtb_11B10_fixed_joint" type="fixed">
    <origin xyz="-0.028587 -0.050082 0.0259155" rpy="1.30899714456 -0.000143911236881 -1.57075776595"/>
    <parent link="r_lower_leg"/>
    <child link="r_lower_leg_acc_mtb_11B10"/>
    <dynamics damping="0.1"/>
  </joint>
  <link name="r_lower_leg_acc_mtb_11B11"/>
  <joint name="r_lower_leg_acc_mtb_11B11_fixed_joint" type="fixed">
    <origin xyz="0.0558761 -0.099573 0.0184576" rpy="-1.30899714532 0.000112146780783 -1.57076627686"/>
    <parent link="r_lower_leg"/>
    <child link="r_lower_leg_acc_mtb_11B11"/>
    <dynamics damping="0.1"/>
  </joint>
  <link name="r_ankle_1">
    <inertial>
      <origin xyz="0.034639 -4.73650698208e-05 0.0151613988639" rpy="0 0 0"/>
      <mass value="0.8929"/>
      <inertia ixx="0.000539928" ixy="-6.33371e-07" ixz="-3.92688e-05" iyy="0.00058171" iyz="1.26546e-06" izz="0.000414634"/>
    </inertial>
  </link>
  <joint name="r_ankle_pitch" type="revolute">
    <origin xyz="-0.021343 -0.201 0" rpy="-2.40788999988e-05 0 0"/>
    <axis xyz="1.0 0.0 0.0"/>
    <parent link="r_lower_leg"/>
    <child link="r_ankle_1"/>
    <limit effort="50000" lower="-0.349065850399" upper="0.523598775598" velocity="50000"/>
    <dynamics damping="0.223"/>
  </joint>
  <link name="r_ankle_2">
    <inertial>
      <origin xyz="-8.19999999999e-06 -0.0382019454736 -0.0437950868735" rpy="0 0 0"/>
      <mass value="0.2675"/>
      <inertia ixx="0.000329604" ixy="6.02821e-07" ixz="7.59365e-08" iyy="0.000253765" iyz="-1.08449e-08" izz="0.000148708"/>
    </inertial>
  </link>
  <joint name="r_ankle_roll" type="revolute">
    <origin xyz="0.0355 0 0.0445624670112" rpy="0 0 0"/>
    <axis xyz="0.0 3.49019587103e-15 -1.00000000029"/>
    <parent link="r_ankle_1"/>
    <child link="r_ankle_2"/>
    <limit effort="50000" lower="-0.349065850399" upper="0.349065850399" velocity="50000"/>
    <dynamics damping="0.223"/>
  </joint>
  <link name="r_foot">
    <inertial>
      <origin xyz="0.033882827801 0.0054048 -0.00115418414893" rpy="-1.57079632708 0 -1.57079632679"/>
      <mass value="0.3794"/>
      <inertia ixx="0.00121493" ixy="-8.90111e-07" ixz="-5.83552e-05" iyy="0.00140898" iyz="-7.84955e-06" izz="0.000283689"/>
    </inertial>
  </link>
  <joint name="r_foot_ft_sensor" type="fixed">
    <origin xyz="0 -0.0603008427249 -0.0480625189919" rpy="3.14159265359 -1.57079632651 -1.57079632679"/>
    <parent link="r_ankle_2"/>
    <child link="r_foot"/>
    <dynamics damping="0.1"/>
  </joint>
  <link name="r_foot_acc_mtb_11B12"/>
  <joint name="r_foot_acc_mtb_11B12_fixed_joint" type="fixed">
    <origin xyz="0.103474429298 -0.000807 -0.00121550847991" rpy="0 0 -1.57079632679"/>
    <parent link="r_foot"/>
    <child link="r_foot_acc_mtb_11B12"/>
    <dynamics damping="0.1"/>
  </joint>
  <link name="r_foot_acc_mtb_11B13"/>
  <joint name="r_foot_acc_mtb_11B13_fixed_joint" type="fixed">
    <origin xyz="0.0784744292809 -0.0118072 -0.00121511044517" rpy="0 0 -1.57079632679"/>
    <parent link="r_foot"/>
    <child link="r_foot_acc_mtb_11B13"/>
    <dynamics damping="0.1"/>
  </joint>
  <link name="r_sole"/>
  <joint name="r_sole_fixed_joint" type="fixed">
    <origin xyz="0 0 0.0144000000055" rpy="-3.14159265359 0 0"/>
    <parent link="r_foot"/>
    <child link="r_sole"/>
    <dynamics damping="0.1"/>
  </joint>
</robot>

